Workbook
Name SegmentaciónDeDatos_Categoria: #N/A
Name SegmentaciónDeDatos_Ciudad: #N/A
Name SegmentaciónDeDatos_Vendedor: #N/A

Sheet Productos
A1: Producto_ID | B1: Producto | C1: Categoría | D1: Marca | E1: Costo | F1: Precio_venta
A2: P001 | B2: Coca Cola 1.5L | C2: Bebidas | D2: Coca-Cola | E2: 2800 | F2: 5000
A3: P002 | B3: Pepsi 1.5L | C3: Bebidas | D3: Pepsi | E3: 2700 | F3: 4800
A4: P003 | B4: Sprite 1.5L | C4: Bebidas | D4: Coca-Cola | E4: 2600 | F4: 4800
A5: P004 | B5: Fanta 1.5L | C5: Bebidas | D5: Coca-Cola | E5: 2600 | F5: 4800
A6: P005 | B6: Agua 600ml | C6: Bebidas | D6: Cristal | E6: 800 | F6: 1500
A7: P006 | B7: Agua 1.5L | C7: Bebidas | D7: Cristal | E7: 1200 | F7: 2000
A8: P007 | B8: Cerveza Aguila | C8: Licores | D8: Bavaria | E8: 1800 | F8: 3000
A9: P008 | B9: Cerveza Poker | C9: Licores | D9: Bavaria | E9: 1750 | F9: 2900
A10: P009 | B10: Cerveza Costeña | C10: Licores | D10: Bavaria | E10: 1700 | F10: 2800
A11: P010 | B11: Whisky mini | C11: Licores | D11: Old Parr | E11: 12000 | F11: 18000
A12: P011 | B12: Vodka | C12: Licores | D12: Smirnoff | E12: 11000 | F12: 17000
A13: P012 | B13: Ron | C13: Licores | D13: Medellín | E13: 9000 | F13: 14000
... A101: P100 | B101: Galletas integrales | C101: Snacks | D101: Noel | E101: 3000 | F101: 5000

Sheet Ventas
A1: Venta_ID | B1: } | C1: Producto_ID | D1: Cantidad | E1: Ciudad | F1: Vendedor | G1: Canal | H1: Producto | I1: Categoria | J1: Precio | K1: Costo | L1: Ingreso | M1: Costo total | N1: Ganancia | O1: Margen de %
A2: V001 | B2: 46174 | C2: P001 | D2: 2 | E2: Medellín | F2: Laura | G2: Tienda | H2: =IFERROR(_xlfn.XLOOKUP(C2,Productos!A:A,Productos!B:B,FALSE),"No encontrado") -> Coca Cola 1.5L | I2: =_xlfn.XLOOKUP(C2,Productos!A:A,Productos!C:C,"No encontrado") -> Bebidas | J2: =_xlfn.XLOOKUP(C2,Productos!A:A,Productos!F:F,"No encontrado") -> 5000 | K2: =_xlfn.XLOOKUP(C2,Productos!A:A,Productos!E:E, "No encontrado") -> 2800 | L2: =IFERROR(D2*J2, 0) -> 10000 | M2: =IFERROR(D2*K2, 0) -> 5600 | N2: =IFERROR(L2-M2, 0) -> 4400 | O2: =IFERROR(ROUND(N2/L2, 2),0) -> 0.44 | Q2: Etiquetas de fila | R2: Suma de Ingreso
A3: V002 | B3: 46174 | C3: P014 | D3: 1 | E3: Bogotá | F3: Felipe | G3: App | H3: =IFERROR(_xlfn.XLOOKUP(C3,Productos!A:A,Productos!B:B,FALSE),"No encontrado") -> Arroz 500g | I3: =_xlfn.XLOOKUP(C3,Productos!A:A,Productos!C:C,"No encontrado") -> Alimentos | J3: =_xlfn.XLOOKUP(C3,Productos!A:A,Productos!F:F,"No encontrado") -> 2000 | K3: =_xlfn.XLOOKUP(C3,Productos!A:A,Productos!E:E, "No encontrado") -> 1300 | L3: =IFERROR(D3*J3, 0) -> 2000 | M3: =IFERROR(D3*K3, 0) -> 1300 | N3: =IFERROR(L3-M3, 0) -> 700 | O3: =IFERROR(ROUND(N3/L3, 2),0) -> 0.35 | Q3: Bogotá | R3: 52000
A4: V003 | B4: 46174 | C4: P025 | D4: 3 | E4: Cali | F4: Andrés | G4: Tienda | H4: =IFERROR(_xlfn.XLOOKUP(C4,Productos!A:A,Productos!B:B,FALSE),"No encontrado") -> Café instantáneo | I4: =_xlfn.XLOOKUP(C4,Productos!A:A,Productos!C:C,"No encontrado") -> Bebidas | J4: =_xlfn.XLOOKUP(C4,Productos!A:A,Productos!F:F,"No encontrado") -> 14000 | K4: =_xlfn.XLOOKUP(C4,Productos!A:A,Productos!E:E, "No encontrado") -> 9000 | L4: =IFERROR(D4*J4, 0) -> 42000 | M4: =IFERROR(D4*K4, 0) -> 27000 | N4: =IFERROR(L4-M4, 0) -> 15000 | O4: =IFERROR(ROUND(N4/L4, 2),0) -> 0.36 | Q4: Cali | R4: 72500
A5: V004 | B5: 46174 | C5: P038 | D5: 1 | E5: Medellín | F5: Laura | G5: App | H5: =IFERROR(_xlfn.XLOOKUP(C5,Productos!A:A,Productos!B:B,FALSE),"No encontrado") -> Papel higiénico x4 | I5: =_xlfn.XLOOKUP(C5,Productos!A:A,Productos!C:C,"No encontrado") -> Aseo | J5: =_xlfn.XLOOKUP(C5,Productos!A:A,Productos!F:F,"No encontrado") -> 8000 | K5: =_xlfn.XLOOKUP(C5,Productos!A:A,Productos!E:E, "No encontrado") -> 5000 | L5: =IFERROR(D5*J5, 0) -> 8000 | M5: =IFERROR(D5*K5, 0) -> 5000 | N5: =IFERROR(L5-M5, 0) -> 3000 | O5: =IFERROR(ROUND(N5/L5, 2),0) -> 0.38 | Q5: Medellín | R5: 36000
A6: V005 | B6: 46174 | C6: P052 | D6: 4 | E6: Bogotá | F6: Felipe | G6: Tienda | H6: =IFERROR(_xlfn.XLOOKUP(C6,Productos!A:A,Productos!B:B,FALSE),"No encontrado") -> Papas Margarita | I6: =_xlfn.XLOOKUP(C6,Productos!A:A,Productos!C:C,"No encontrado") -> Snacks | J6: =_xlfn.XLOOKUP(C6,Productos!A:A,Productos!F:F,"No encontrado") -> 3000 | K6: =_xlfn.XLOOKUP(C6,Productos!A:A,Productos!E:E, "No encontrado") -> 1800 | L6: =IFERROR(D6*J6, 0) -> 12000 | M6: =IFERROR(D6*K6, 0) -> 7200 | N6: =IFERROR(L6-M6, 0) -> 4800 | O6: =IFERROR(ROUND(N6/L6, 2),0) -> 0.4 | Q6: Total general | R6: 160500
A7: V006 | B7: 46175 | C7: P009 | D7: 2 | E7: Cali | F7: Andrés | G7: App | H7: =IFERROR(_xlfn.XLOOKUP(C7,Productos!A:A,Productos!B:B,FALSE),"No encontrado") -> Cerveza Costeña | I7: =_xlfn.XLOOKUP(C7,Productos!A:A,Productos!C:C,"No encontrado") -> Licores | J7: =_xlfn.XLOOKUP(C7,Productos!A:A,Productos!F:F,"No encontrado") -> 2800 | K7: =_xlfn.XLOOKUP(C7,Productos!A:A,Productos!E:E, "No encontrado") -> 1700 | L7: =IFERROR(D7*J7, 0) -> 5600 | M7: =IFERROR(D7*K7, 0) -> 3400 | N7: =IFERROR(L7-M7, 0) -> 2200 | O7: =IFERROR(ROUND(N7/L7, 2),0) -> 0.39 | Q7: Etiquetas de fila | R7: Suma de Ganancia
A8: V007 | B8: 46175 | C8: P033 | D8: 1 | E8: Medellín | F8: Laura | G8: Tienda | H8: =IFERROR(_xlfn.XLOOKUP(C8,Productos!A:A,Productos!B:B,FALSE),"No encontrado") -> Pollo | I8: =_xlfn.XLOOKUP(C8,Productos!A:A,Productos!C:C,"No encontrado") -> Proteína | J8: =_xlfn.XLOOKUP(C8,Productos!A:A,Productos!F:F,"No encontrado") -> 12000 | K8: =_xlfn.XLOOKUP(C8,Productos!A:A,Productos!E:E, "No encontrado") -> 8000 | L8: =IFERROR(D8*J8, 0) -> 12000 | M8: =IFERROR(D8*K8, 0) -> 8000 | N8: =IFERROR(L8-M8, 0) -> 4000 | O8: =IFERROR(ROUND(N8/L8, 2),0) -> 0.33 | Q8: Alimentos | R8: 36400
A9: V008 | B9: 46175 | C9: P067 | D9: 2 | E9: Bogotá | F9: Felipe | G9: App | H9: =IFERROR(_xlfn.XLOOKUP(C9,Productos!A:A,Productos!B:B,FALSE),"No encontrado") -> Mostaza | I9: =_xlfn.XLOOKUP(C9,Productos!A:A,Productos!C:C,"No encontrado") -> Alimentos | J9: =_xlfn.XLOOKUP(C9,Productos!A:A,Productos!F:F,"No encontrado") -> 5000 | K9: =_xlfn.XLOOKUP(C9,Productos!A:A,Productos!E:E, "No encontrado") -> 3000 | L9: =IFERROR(D9*J9, 0) -> 10000 | M9: =IFERROR(D9*K9, 0) -> 6000 | N9: =IFERROR(L9-M9, 0) -> 4000 | O9: =IFERROR(ROUND(N9/L9, 2),0) -> 0.4 | Q9: Aseo | R9: 59000
A10: V009 | B10: 46175 | C10: P081 | D10: 5 | E10: Cali | F10: Andrés | G10: Tienda | H10: =IFERROR(_xlfn.XLOOKUP(C10,Productos!A:A,Productos!B:B,FALSE),"No encontrado") -> Galletas festival | I10: =_xlfn.XLOOKUP(C10,Productos!A:A,Productos!C:C,"No encontrado") -> Snacks | J10: =_xlfn.XLOOKUP(C10,Productos!A:A,Productos!F:F,"No encontrado") -> 3200 | K10: =_xlfn.XLOOKUP(C10,Productos!A:A,Productos!E:E, "No encontrado") -> 2000 | L10: =IFERROR(D10*J10, 0) -> 16000 | M10: =IFERROR(D10*K10, 0) -> 10000 | N10: =IFERROR(L10-M10, 0) -> 6000 | O10: =IFERROR(ROUND(N10/L10, 2),0) -> 0.38 | Q10: Bebidas | R10: 55600
A11: V010 | B11: 46175 | C11: P099 | D11: 2 | E11: Medellín | F11: Laura | G11: App | H11: =IFERROR(_xlfn.XLOOKUP(C11,Productos!A:A,Productos!B:B,FALSE),"No encontrado") -> Agua saborizada | I11: =_xlfn.XLOOKUP(C11,Productos!A:A,Productos!C:C,"No encontrado") -> Bebidas | J11: =_xlfn.XLOOKUP(C11,Productos!A:A,Productos!F:F,"No encontrado") -> 2500 | K11: =_xlfn.XLOOKUP(C11,Productos!A:A,Productos!E:E, "No encontrado") -> 1500 | L11: =IFERROR(D11*J11, 0) -> 5000 | M11: =IFERROR(D11*K11, 0) -> 3000 | N11: =IFERROR(L11-M11, 0) -> 2000 | O11: =IFERROR(ROUND(N11/L11, 2),0) -> 0.4 | Q11: Lácteos | R11: 25400
A12: V011 | B12: 46176 | C12: P020 | D12: 1 | E12: Bogotá | F12: Felipe | G12: Tienda | H12: =IFERROR(_xlfn.XLOOKUP(C12,Productos!A:A,Productos!B:B,FALSE),"No encontrado") -> Aceite 1L | I12: =_xlfn.XLOOKUP(C12,Productos!A:A,Productos!C:C,"No encontrado") -> Alimentos | J12: =_xlfn.XLOOKUP(C12,Productos!A:A,Productos!F:F,"No encontrado") -> 12000 | K12: =_xlfn.XLOOKUP(C12,Productos!A:A,Productos!E:E, "No encontrado") -> 8500 | L12: =IFERROR(D12*J12, 0) -> 12000 | M12: =IFERROR(D12*K12, 0) -> 8500 | N12: =IFERROR(L12-M12, 0) -> 3500 | O12: =IFERROR(ROUND(N12/L12, 2),0) -> 0.29 | Q12: Licores | R12: 18200
A13: V012 | B13: 46176 | C13: P045 | D13: 3 | E13: Cali | F13: Andrés | G13: App | H13: =IFERROR(_xlfn.XLOOKUP(C13,Productos!A:A,Productos!B:B,FALSE),"No encontrado") -> Desinfectante | I13: =_xlfn.XLOOKUP(C13,Productos!A:A,Productos!C:C,"No encontrado") -> Aseo | J13: =_xlfn.XLOOKUP(C13,Productos!A:A,Productos!F:F,"No encontrado") -> 6500 | K13: =_xlfn.XLOOKUP(C13,Productos!A:A,Productos!E:E, "No encontrado") -> 4000 | L13: =IFERROR(D13*J13, 0) -> 19500 | M13: =IFERROR(D13*K13, 0) -> 12000 | N13: =IFERROR(L13-M13, 0) -> 7500 | O13: =IFERROR(ROUND(N13/L13, 2),0) -> 0.38 | Q13: No encontrado | R13: 0
A14: V013 | B14: 46176 | C14: P060 | D14: 2 | E14: Medellín | F14: Laura | G14: Tienda | H14: =IFERROR(_xlfn.XLOOKUP(C14,Productos!A:A,Productos!B:B,FALSE),"No encontrado") -> Jugo Del Valle | I14: =_xlfn.XLOOKUP(C14,Productos!A:A,Productos!C:C,"No encontrado") -> Bebidas | J14: =_xlfn.XLOOKUP(C14,Productos!A:A,Productos!F:F,"No encontrado") -> 3500 | K14: =_xlfn.XLOOKUP(C14,Productos!A:A,Productos!E:E, "No encontrado") -> 2000 | L14: =IFERROR(D14*J14, 0) -> 7000 | M14: =IFERROR(D14*K14, 0) -> 4000 | N14: =IFERROR(L14-M14, 0) -> 3000 | O14: =IFERROR(ROUND(N14/L14, 2),0) -> 0.43 | Q14: Panadería | R14: 3800
A15: V014 | B15: 46176 | C15: P075 | D15: 1 | E15: Bogotá | F15: Felipe | G15: App | H15: =IFERROR(_xlfn.XLOOKUP(C15,Productos!A:A,Productos!B:B,FALSE),"No encontrado") -> Leche en polvo | I15: =_xlfn.XLOOKUP(C15,Productos!A:A,Productos!C:C,"No encontrado") -> Lácteos | J15: =_xlfn.XLOOKUP(C15,Productos!A:A,Productos!F:F,"No encontrado") -> 14000 | K15: =_xlfn.XLOOKUP(C15,Productos!A:A,Productos!E:E, "No encontrado") -> 9000 | L15: =IFERROR(D15*J15, 0) -> 14000 | M15: =IFERROR(D15*K15, 0) -> 9000 | N15: =IFERROR(L15-M15, 0) -> 5000 | O15: =IFERROR(ROUND(N15/L15, 2),0) -> 0.36 | Q15: Proteína | R15: 9000
A16: V015 | B16: 46176 | C16: P088 | D16: 4 | E16: Cali | F16: Andrés | G16: Tienda | H16: =IFERROR(_xlfn.XLOOKUP(C16,Productos!A:A,Productos!B:B,FALSE),"No encontrado") -> Toallas húmedas | I16: =_xlfn.XLOOKUP(C16,Productos!A:A,Productos!C:C,"No encontrado") -> Aseo | J16: =_xlfn.XLOOKUP(C16,Productos!A:A,Productos!F:F,"No encontrado") -> 6500 | K16: =_xlfn.XLOOKUP(C16,Productos!A:A,Productos!E:E, "No encontrado") -> 4000 | L16: =IFERROR(D16*J16, 0) -> 26000 | M16: =IFERROR(D16*K16, 0) -> 16000 | N16: =IFERROR(L16-M16, 0) -> 10000 | O16: =IFERROR(ROUND(N16/L16, 2),0) -> 0.38 | Q16: Snacks | R16: 22900
A17: V016 | B17: 46177 | C17: P003 | D17: 2 | E17: Medellín | F17: Laura | G17: App | H17: =IFERROR(_xlfn.XLOOKUP(C17,Productos!A:A,Productos!B:B,FALSE),"No encontrado") -> Sprite 1.5L | I17: =_xlfn.XLOOKUP(C17,Productos!A:A,Productos!C:C,"No encontrado") -> Bebidas | J17: =_xlfn.XLOOKUP(C17,Productos!A:A,Productos!F:F,"No encontrado") -> 4800 | K17: =_xlfn.XLOOKUP(C17,Productos!A:A,Productos!E:E, "No encontrado") -> 2600 | L17: =IFERROR(D17*J17, 0) -> 9600 | M17: =IFERROR(D17*K17, 0) -> 5200 | N17: =IFERROR(L17-M17, 0) -> 4400 | O17: =IFERROR(ROUND(N17/L17, 2),0) -> 0.46 | Q17: Total general | R17: 230300
A18: V017 | B18: 46177 | C18: P017 | D18: 1 | E18: Bogotá | F18: Felipe | G18: Tienda | H18: =IFERROR(_xlfn.XLOOKUP(C18,Productos!A:A,Productos!B:B,FALSE),"No encontrado") -> Garbanzo | I18: =_xlfn.XLOOKUP(C18,Productos!A:A,Productos!C:C,"No encontrado") -> Alimentos | J18: =_xlfn.XLOOKUP(C18,Productos!A:A,Productos!F:F,"No encontrado") -> 3600 | K18: =_xlfn.XLOOKUP(C18,Productos!A:A,Productos!E:E, "No encontrado") -> 2600 | L18: =IFERROR(D18*J18, 0) -> 3600 | M18: =IFERROR(D18*K18, 0) -> 2600 | N18: =IFERROR(L18-M18, 0) -> 1000 | O18: =IFERROR(ROUND(N18/L18, 2),0) -> 0.28 | Q18: Etiquetas de fila | R18: Suma de Ingreso
A19: V018 | B19: 46177 | C19: P031 | D19: 3 | E19: Cali | F19: Andrés | G19: App | H19: =IFERROR(_xlfn.XLOOKUP(C19,Productos!A:A,Productos!B:B,FALSE),"No encontrado") -> Mantequilla | I19: =_xlfn.XLOOKUP(C19,Productos!A:A,Productos!C:C,"No encontrado") -> Lácteos | J19: =_xlfn.XLOOKUP(C19,Productos!A:A,Productos!F:F,"No encontrado") -> 5000 | K19: =_xlfn.XLOOKUP(C19,Productos!A:A,Productos!E:E, "No encontrado") -> 3500 | L19: =IFERROR(D19*J19, 0) -> 15000 | M19: =IFERROR(D19*K19, 0) -> 10500 | N19: =IFERROR(L19-M19, 0) -> 4500 | O19: =IFERROR(ROUND(N19/L19, 2),0) -> 0.3 | Q19: Acondicionador | R19: 18000
A20: V019 | B20: 46177 | C20: P049 | D20: 2 | E20: Medellín | F20: Laura | G20: Tienda | H20: =IFERROR(_xlfn.XLOOKUP(C20,Productos!A:A,Productos!B:B,FALSE),"No encontrado") -> Oreo | I20: =_xlfn.XLOOKUP(C20,Productos!A:A,Productos!C:C,"No encontrado") -> Snacks | J20: =_xlfn.XLOOKUP(C20,Productos!A:A,Productos!F:F,"No encontrado") -> 3000 | K20: =_xlfn.XLOOKUP(C20,Productos!A:A,Productos!E:E, "No encontrado") -> 1800 | L20: =IFERROR(D20*J20, 0) -> 6000 | M20: =IFERROR(D20*K20, 0) -> 3600 | N20: =IFERROR(L20-M20, 0) -> 2400 | O20: =IFERROR(ROUND(N20/L20, 2),0) -> 0.4 | Q20: Café instantáneo | R20: 42000
A21: V020 | B21: 46177 | C21: P070 | D21: 1 | E21: Bogotá | F21: Felipe | G21: App | H21: =IFERROR(_xlfn.XLOOKUP(C21,Productos!A:A,Productos!B:B,FALSE),"No encontrado") -> Arvejas | I21: =_xlfn.XLOOKUP(C21,Productos!A:A,Productos!C:C,"No encontrado") -> Alimentos | J21: =_xlfn.XLOOKUP(C21,Productos!A:A,Productos!F:F,"No encontrado") -> 3200 | K21: =_xlfn.XLOOKUP(C21,Productos!A:A,Productos!E:E, "No encontrado") -> 2000 | L21: =IFERROR(D21*J21, 0) -> 3200 | M21: =IFERROR(D21*K21, 0) -> 2000 | N21: =IFERROR(L21-M21, 0) -> 1200 | O21: =IFERROR(ROUND(N21/L21, 2),0) -> 0.38 | Q21: Desinfectante | R21: 19500
A22: V021 | B22: 46178 | C22: P012 | D22: 2 | E22: Cali | F22: Andrés | G22: Tienda | H22: =IFERROR(_xlfn.XLOOKUP(C22,Productos!A:A,Productos!B:B,FALSE),"No encontrado") -> Ron | I22: =_xlfn.XLOOKUP(C22,Productos!A:A,Productos!C:C,"No encontrado") -> Licores | J22: =_xlfn.XLOOKUP(C22,Productos!A:A,Productos!F:F,"No encontrado") -> 14000 | K22: =_xlfn.XLOOKUP(C22,Productos!A:A,Productos!E:E, "No encontrado") -> 9000 | L22: =IFERROR(D22*J22, 0) -> 28000 | M22: =IFERROR(D22*K22, 0) -> 18000 | N22: =IFERROR(L22-M22, 0) -> 10000 | O22: =IFERROR(ROUND(N22/L22, 2),0) -> 0.36 | Q22: Galletas festival | R22: 16000
A23: V022 | B23: 46178 | C23: P028 | D23: 1 | E23: Medellín | F23: Laura | G23: App | H23: =IFERROR(_xlfn.XLOOKUP(C23,Productos!A:A,Productos!B:B,FALSE),"No encontrado") -> Leche deslactosada | I23: =_xlfn.XLOOKUP(C23,Productos!A:A,Productos!C:C,"No encontrado") -> Lácteos | J23: =_xlfn.XLOOKUP(C23,Productos!A:A,Productos!F:F,"No encontrado") -> 4500 | K23: =_xlfn.XLOOKUP(C23,Productos!A:A,Productos!E:E, "No encontrado") -> 3200 | L23: =IFERROR(D23*J23, 0) -> 4500 | M23: =IFERROR(D23*K23, 0) -> 3200 | N23: =IFERROR(L23-M23, 0) -> 1300 | O23: =IFERROR(ROUND(N23/L23, 2),0) -> 0.29 | Q23: Mayonesa | R23: 19500
A24: V023 | B24: 46178 | C24: P041 | D24: 3 | E24: Bogotá | F24: Felipe | G24: Tienda | H24: =IFERROR(_xlfn.XLOOKUP(C24,Productos!A:A,Productos!B:B,FALSE),"No encontrado") -> Shampoo | I24: =_xlfn.XLOOKUP(C24,Productos!A:A,Productos!C:C,"No encontrado") -> Aseo | J24: =_xlfn.XLOOKUP(C24,Productos!A:A,Productos!F:F,"No encontrado") -> 9000 | K24: =_xlfn.XLOOKUP(C24,Productos!A:A,Productos!E:E, "No encontrado") -> 6000 | L24: =IFERROR(D24*J24, 0) -> 27000 | M24: =IFERROR(D24*K24, 0) -> 18000 | N24: =IFERROR(L24-M24, 0) -> 9000 | O24: =IFERROR(ROUND(N24/L24, 2),0) -> 0.33 | Q24: Papel higiénico x8 | R24: 28000
A25: V024 | B25: 46178 | C25: P056 | D25: 2 | E25: Cali | F25: Andrés | G25: App | H25: =IFERROR(_xlfn.XLOOKUP(C25,Productos!A:A,Productos!B:B,FALSE),"No encontrado") -> Tortilla | I25: =_xlfn.XLOOKUP(C25,Productos!A:A,Productos!C:C,"No encontrado") -> Panadería | J25: =_xlfn.XLOOKUP(C25,Productos!A:A,Productos!F:F,"No encontrado") -> 3500 | K25: =_xlfn.XLOOKUP(C25,Productos!A:A,Productos!E:E, "No encontrado") -> 2000 | L25: =IFERROR(D25*J25, 0) -> 7000 | M25: =IFERROR(D25*K25, 0) -> 4000 | N25: =IFERROR(L25-M25, 0) -> 3000 | O25: =IFERROR(ROUND(N25/L25, 2),0) -> 0.43 | Q25: Ron | R25: 28000
A26: V025 | B26: 46178 | C26: P064 | D26: 1 | E26: Medellín | F26: Laura | G26: Tienda | H26: =IFERROR(_xlfn.XLOOKUP(C26,Productos!A:A,Productos!B:B,FALSE),"No encontrado") -> Gaseosa 2.5L | I26: =_xlfn.XLOOKUP(C26,Productos!A:A,Productos!C:C,"No encontrado") -> Bebidas | J26: =_xlfn.XLOOKUP(C26,Productos!A:A,Productos!F:F,"No encontrado") -> 6500 | K26: =_xlfn.XLOOKUP(C26,Productos!A:A,Productos!E:E, "No encontrado") -> 4000 | L26: =IFERROR(D26*J26, 0) -> 6500 | M26: =IFERROR(D26*K26, 0) -> 4000 | N26: =IFERROR(L26-M26, 0) -> 2500 | O26: =IFERROR(ROUND(N26/L26, 2),0) -> 0.38 | Q26: Shampoo | R26: 27000
A27: V026 | B27: 46179 | C27: P073 | D27: 2 | E27: Bogotá | F27: Felipe | G27: App | H27: =IFERROR(_xlfn.XLOOKUP(C27,Productos!A:A,Productos!B:B,FALSE),"No encontrado") -> Panela | I27: =_xlfn.XLOOKUP(C27,Productos!A:A,Productos!C:C,"No encontrado") -> Alimentos | J27: =_xlfn.XLOOKUP(C27,Productos!A:A,Productos!F:F,"No encontrado") -> 4000 | K27: =_xlfn.XLOOKUP(C27,Productos!A:A,Productos!E:E, "No encontrado") -> 2500 | L27: =IFERROR(D27*J27, 0) -> 8000 | M27: =IFERROR(D27*K27, 0) -> 5000 | N27: =IFERROR(L27-M27, 0) -> 3000 | O27: =IFERROR(ROUND(N27/L27, 2),0) -> 0.38 | Q27: Toallas húmedas | R27: 26000
A28: V027 | B28: 46179 | C28: P086 | D28: 1 | E28: Cali | F28: Andrés | G28: Tienda | H28: =IFERROR(_xlfn.XLOOKUP(C28,Productos!A:A,Productos!B:B,FALSE),"No encontrado") -> Pasta dental | I28: =_xlfn.XLOOKUP(C28,Productos!A:A,Productos!C:C,"No encontrado") -> Aseo | J28: =_xlfn.XLOOKUP(C28,Productos!A:A,Productos!F:F,"No encontrado") -> 6000 | K28: =_xlfn.XLOOKUP(C28,Productos!A:A,Productos!E:E, "No encontrado") -> 3500 | L28: =IFERROR(D28*J28, 0) -> 6000 | M28: =IFERROR(D28*K28, 0) -> 3500 | N28: =IFERROR(L28-M28, 0) -> 2500 | O28: =IFERROR(ROUND(N28/L28, 2),0) -> 0.42 | Q28: Whisky mini | R28: 18000
A29: V028 | B29: 46179 | C29: P092 | D29: 3 | E29: Medellín | F29: Laura | G29: App | H29: =IFERROR(_xlfn.XLOOKUP(C29,Productos!A:A,Productos!B:B,FALSE),"No encontrado") -> Arroz integral | I29: =_xlfn.XLOOKUP(C29,Productos!A:A,Productos!C:C,"No encontrado") -> Alimentos | J29: =_xlfn.XLOOKUP(C29,Productos!A:A,Productos!F:F,"No encontrado") -> 4500 | K29: =_xlfn.XLOOKUP(C29,Productos!A:A,Productos!E:E, "No encontrado") -> 3000 | L29: =IFERROR(D29*J29, 0) -> 13500 | M29: =IFERROR(D29*K29, 0) -> 9000 | N29: =IFERROR(L29-M29, 0) -> 4500 | O29: =IFERROR(ROUND(N29/L29, 2),0) -> 0.33 | Q29: Total general | R29: 242000
A30: V029 | B30: 46179 | C30: P097 | D30: 2 | E30: Bogotá | F30: Felipe | G30: Tienda | H30: =IFERROR(_xlfn.XLOOKUP(C30,Productos!A:A,Productos!B:B,FALSE),"No encontrado") -> Leche chocolatada | I30: =_xlfn.XLOOKUP(C30,Productos!A:A,Productos!C:C,"No encontrado") -> Lácteos | J30: =_xlfn.XLOOKUP(C30,Productos!A:A,Productos!F:F,"No encontrado") -> 4000 | K30: =_xlfn.XLOOKUP(C30,Productos!A:A,Productos!E:E, "No encontrado") -> 2500 | L30: =IFERROR(D30*J30, 0) -> 8000 | M30: =IFERROR(D30*K30, 0) -> 5000 | N30: =IFERROR(L30-M30, 0) -> 3000 | O30: =IFERROR(ROUND(N30/L30, 2),0) -> 0.38
A31: V030 | B31: 46179 | C31: P010 | D31: 1 | E31: Cali | F31: Andrés | G31: App | H31: =IFERROR(_xlfn.XLOOKUP(C31,Productos!A:A,Productos!B:B,FALSE),"No encontrado") -> Whisky mini | I31: =_xlfn.XLOOKUP(C31,Productos!A:A,Productos!C:C,"No encontrado") -> Licores | J31: =_xlfn.XLOOKUP(C31,Productos!A:A,Productos!F:F,"No encontrado") -> 18000 | K31: =_xlfn.XLOOKUP(C31,Productos!A:A,Productos!E:E, "No encontrado") -> 12000 | L31: =IFERROR(D31*J31, 0) -> 18000 | M31: =IFERROR(D31*K31, 0) -> 12000 | N31: =IFERROR(L31-M31, 0) -> 6000 | O31: =IFERROR(ROUND(N31/L31, 2),0) -> 0.33
A32: V031 | B32: 46180 | C32: P021 | D32: 2 | E32: Medellín | F32: Laura | G32: Tienda | H32: =IFERROR(_xlfn.XLOOKUP(C32,Productos!A:A,Productos!B:B,FALSE),"No encontrado") -> Azúcar 1kg | I32: =_xlfn.XLOOKUP(C32,Productos!A:A,Productos!C:C,"No encontrado") -> Alimentos | J32: =_xlfn.XLOOKUP(C32,Productos!A:A,Productos!F:F,"No encontrado") -> 3800 | K32: =_xlfn.XLOOKUP(C32,Productos!A:A,Productos!E:E, "No encontrado") -> 2600 | L32: =IFERROR(D32*J32, 0) -> 7600 | M32: =IFERROR(D32*K32, 0) -> 5200 | N32: =IFERROR(L32-M32, 0) -> 2400 | O32: =IFERROR(ROUND(N32/L32, 2),0) -> 0.32
A33: V032 | B33: 46180 | C33: P034 | D33: 1 | E33: Bogotá | F33: Felipe | G33: App | H33: =IFERROR(_xlfn.XLOOKUP(C33,Productos!A:A,Productos!B:B,FALSE),"No encontrado") -> Carne molida | I33: =_xlfn.XLOOKUP(C33,Productos!A:A,Productos!C:C,"No encontrado") -> Proteína | J33: =_xlfn.XLOOKUP(C33,Productos!A:A,Productos!F:F,"No encontrado") -> 15000 | K33: =_xlfn.XLOOKUP(C33,Productos!A:A,Productos!E:E, "No encontrado") -> 10000 | L33: =IFERROR(D33*J33, 0) -> 15000 | M33: =IFERROR(D33*K33, 0) -> 10000 | N33: =IFERROR(L33-M33, 0) -> 5000 | O33: =IFERROR(ROUND(N33/L33, 2),0) -> 0.33
A34: V033 | B34: 46180 | C34: P047 | D34: 3 | E34: Cali | F34: Andrés | G34: Tienda | H34: =IFERROR(_xlfn.XLOOKUP(C34,Productos!A:A,Productos!B:B,FALSE),"No encontrado") -> Doritos | I34: =_xlfn.XLOOKUP(C34,Productos!A:A,Productos!C:C,"No encontrado") -> Snacks | J34: =_xlfn.XLOOKUP(C34,Productos!A:A,Productos!F:F,"No encontrado") -> 1600 | K34: =_xlfn.XLOOKUP(C34,Productos!A:A,Productos!E:E, "No encontrado") -> 900 | L34: =IFERROR(D34*J34, 0) -> 4800 | M34: =IFERROR(D34*K34, 0) -> 2700 | N34: =IFERROR(L34-M34, 0) -> 2100 | O34: =IFERROR(ROUND(N34/L34, 2),0) -> 0.44
A35: V034 | B35: 46180 | C35: P059 | D35: 2 | E35: Medellín | F35: Laura | G35: App | H35: =IFERROR(_xlfn.XLOOKUP(C35,Productos!A:A,Productos!B:B,FALSE),"No encontrado") -> Jugo Hit | I35: =_xlfn.XLOOKUP(C35,Productos!A:A,Productos!C:C,"No encontrado") -> Bebidas | J35: =_xlfn.XLOOKUP(C35,Productos!A:A,Productos!F:F,"No encontrado") -> 3000 | K35: =_xlfn.XLOOKUP(C35,Productos!A:A,Productos!E:E, "No encontrado") -> 1800 | L35: =IFERROR(D35*J35, 0) -> 6000 | M35: =IFERROR(D35*K35, 0) -> 3600 | N35: =IFERROR(L35-M35, 0) -> 2400 | O35: =IFERROR(ROUND(N35/L35, 2),0) -> 0.4
A36: V035 | B36: 46180 | C36: P071 | D36: 1 | E36: Bogotá | F36: Felipe | G36: Tienda | H36: =IFERROR(_xlfn.XLOOKUP(C36,Productos!A:A,Productos!B:B,FALSE),"No encontrado") -> Maíz | I36: =_xlfn.XLOOKUP(C36,Productos!A:A,Productos!C:C,"No encontrado") -> Alimentos | J36: =_xlfn.XLOOKUP(C36,Productos!A:A,Productos!F:F,"No encontrado") -> 3200 | K36: =_xlfn.XLOOKUP(C36,Productos!A:A,Productos!E:E, "No encontrado") -> 2000 | L36: =IFERROR(D36*J36, 0) -> 3200 | M36: =IFERROR(D36*K36, 0) -> 2000 | N36: =IFERROR(L36-M36, 0) -> 1200 | O36: =IFERROR(ROUND(N36/L36, 2),0) -> 0.38
A37: V036 | B37: 46181 | C37: P082 | D37: 2 | E37: Cali | F37: Andrés | G37: App | H37: =IFERROR(_xlfn.XLOOKUP(C37,Productos!A:A,Productos!B:B,FALSE),"No encontrado") -> Chocolatina jumbo | I37: =_xlfn.XLOOKUP(C37,Productos!A:A,Productos!C:C,"No encontrado") -> Snacks | J37: =_xlfn.XLOOKUP(C37,Productos!A:A,Productos!F:F,"No encontrado") -> 5000 | K37: =_xlfn.XLOOKUP(C37,Productos!A:A,Productos!E:E, "No encontrado") -> 3000 | L37: =IFERROR(D37*J37, 0) -> 10000 | M37: =IFERROR(D37*K37, 0) -> 6000 | N37: =IFERROR(L37-M37, 0) -> 4000 | O37: =IFERROR(ROUND(N37/L37, 2),0) -> 0.4
A38: V037 | B38: 46181 | C38: P093 | D38: 1 | E38: Medellín | F38: Laura | G38: Tienda | H38: =IFERROR(_xlfn.XLOOKUP(C38,Productos!A:A,Productos!B:B,FALSE),"No encontrado") -> Quinua | I38: =_xlfn.XLOOKUP(C38,Productos!A:A,Productos!C:C,"No encontrado") -> Alimentos | J38: =_xlfn.XLOOKUP(C38,Productos!A:A,Productos!F:F,"No encontrado") -> 9000 | K38: =_xlfn.XLOOKUP(C38,Productos!A:A,Productos!E:E, "No encontrado") -> 6000 | L38: =IFERROR(D38*J38, 0) -> 9000 | M38: =IFERROR(D38*K38, 0) -> 6000 | N38: =IFERROR(L38-M38, 0) -> 3000 | O38: =IFERROR(ROUND(N38/L38, 2),0) -> 0.33
A39: V038 | B39: 46181 | C39: P006 | D39: 3 | E39: Bogotá | F39: Felipe | G39: App | H39: =IFERROR(_xlfn.XLOOKUP(C39,Productos!A:A,Productos!B:B,FALSE),"No encontrado") -> Agua 1.5L | I39: =_xlfn.XLOOKUP(C39,Productos!A:A,Productos!C:C,"No encontrado") -> Bebidas | J39: =_xlfn.XLOOKUP(C39,Productos!A:A,Productos!F:F,"No encontrado") -> 2000 | K39: =_xlfn.XLOOKUP(C39,Productos!A:A,Productos!E:E, "No encontrado") -> 1200 | L39: =IFERROR(D39*J39, 0) -> 6000 | M39: =IFERROR(D39*K39, 0) -> 3600 | N39: =IFERROR(L39-M39, 0) -> 2400 | O39: =IFERROR(ROUND(N39/L39, 2),0) -> 0.4
A40: V039 | B40: 46181 | C40: P018 | D40: 2 | E40: Cali | F40: Andrés | G40: Tienda | H40: =IFERROR(_xlfn.XLOOKUP(C40,Productos!A:A,Productos!B:B,FALSE),"No encontrado") -> Pasta 500g | I40: =_xlfn.XLOOKUP(C40,Productos!A:A,Productos!C:C,"No encontrado") -> Alimentos | J40: =_xlfn.XLOOKUP(C40,Productos!A:A,Productos!F:F,"No encontrado") -> 3000 | K40: =_xlfn.XLOOKUP(C40,Productos!A:A,Productos!E:E, "No encontrado") -> 1800 | L40: =IFERROR(D40*J40, 0) -> 6000 | M40: =IFERROR(D40*K40, 0) -> 3600 | N40: =IFERROR(L40-M40, 0) -> 2400 | O40: =IFERROR(ROUND(N40/L40, 2),0) -> 0.4
...

Sheet Dashboard 
G1: DASHBOARD DE VENTAS
T4: TOTAL VENTAS
T6: =SUM(Ventas!L2:L1000) -> 624500
T17: VENTA MAS ALTA
T19: =MAX(Ventas!L2:L200) -> 42000
T30: VENTA MAS BAJA
T32: =_xlfn.MINIFS(Ventas!L2:L200,Ventas!L2:L200,">0") -> 2000
T43: PROMEDIO VENTAS
T45: =AVERAGE(Ventas!L2:L200) -> 10237.705
